Scanning for devices...
Traceback (most recent call last):
  File "/opt/homebrew/Cellar/python@3.13/3.13.7/Frameworks/Python.framework/Versions/3.13/lib/python3.13/asyncio/runners.py", line 118, in run
    return self._loop.run_until_complete(task)
           ~~~~~~~~~~~~~~~~~~~~~~~~~~~~~^^^^^^
  File "/opt/homebrew/Cellar/python@3.13/3.13.7/Frameworks/Python.framework/Versions/3.13/lib/python3.13/asyncio/base_events.py", line 725, in run_until_complete
    return future.result()
           ~~~~~~~~~~~~~^^
  File "/Users/j/8803/project/tester.py", line 42, in main
    devices = await BleakScanner.discover()
              ^^^^^^^^^^^^^^^^^^^^^^^^^^^^^
  File "/Users/j/8803/project/my-venv/lib/python3.13/site-packages/bleak/__init__.py", line 264, in discover
    await asyncio.sleep(timeout)
  File "/opt/homebrew/Cellar/python@3.13/3.13.7/Frameworks/Python.framework/Versions/3.13/lib/python3.13/asyncio/tasks.py", line 718, in sleep
    return await future
           ^^^^^^^^^^^^
asyncio.exceptions.CancelledError

During handling of the above exception, another exception occurred:

Traceback (most recent call last):
  File "/Users/j/8803/project/tester.py", line 58, in <module>
    asyncio.run(main())
    ~~~~~~~~~~~^^^^^^^^
  File "/opt/homebrew/Cellar/python@3.13/3.13.7/Frameworks/Python.framework/Versions/3.13/lib/python3.13/asyncio/runners.py", line 195, in run
    return runner.run(main)
           ~~~~~~~~~~^^^^^^
  File "/opt/homebrew/Cellar/python@3.13/3.13.7/Frameworks/Python.framework/Versions/3.13/lib/python3.13/asyncio/runners.py", line 123, in run
    raise KeyboardInterrupt()
KeyboardInterrupt
